<?xml version="1.0" ?>
<!-- =================================================================================== -->
<!-- |    This document was autogenerated by xacro from qingzhui2.urdf.xacro           | -->
<!-- |    EDITING THIS FILE BY HAND IS NOT RECOMMENDED                                 | -->
<!-- =================================================================================== -->
<robot name="qingzhui2">
  <!--Hexapod Descritopn, Containing One Base and Six Legs-->
  <link name="world"/>
  <joint name="floating_base_joint" type="floating">
    <origin rpy="0 0 0" xyz="0 0 0"/>
    <parent link="world"/>
    <child link="base"/>
  </joint>
  <!--<link name="base_sensor">
        <visual>
            <geometry>
                <box size="0.001 0.001 0.001" />
            </geometry>
            <origin rpy="0 0 0" xyz="0 0 0"/>
            <xacro:red/>
        </visual>
    </link>

    <joint name="base_Aux" type="fixed">
        <origin rpy="0 0 0" xyz="0 0 0"/>
        <parent link="base_sensor"/>
        <child link="base"/>
    </joint>-->
  <link name="base">
    <inertial>
      <origin xyz="0 0 0"/>
      <mass value="26.60"/>
      <inertia ixx="0.43202" ixy="0" ixz="0" iyy="0.59440" iyz="0" izz="0.98210"/>
    </inertial>
    <visual>
      <geometry>
        <mesh filename="/home/dada/mujoco/qz2_urdf/qz2_meshes/base.STL" scale="0.001 0.001 0.001"/>
      </geometry>
      <origin rpy="1.570795 0 1.570795" xyz="0 0 0"/>
      <material name="red">
        <color rgba="1.0 0.3 0.3 0.3"/>
      </material>
    </visual>
    <collision>
      <geometry>
        <mesh filename="/home/dada/mujoco/qz2_urdf/qz2_meshes/base.STL" scale="0.001 0.001 0.001"/>
      </geometry>
      <origin rpy="1.570795 0 1.570795" xyz="0 0 0"/>
    </collision>
  </link>
  <!-- Extensions -->
  <!-- Joints -->
  <!-- Hip assembly joint -->
  <joint name="L0_hip_joint" type="revolute">
    <parent link="base"/>
    <child link="L0_hipassembly"/>
    <axis xyz="1 0 0"/>
    <origin rpy="0 0 0" xyz="0.510043 0 0"/>
    <limit effort="500.0" lower="-0.84" upper="0.84" velocity="12.0"/>
    <dynamics damping="0.1" friction="0.1"/>
    <!--<safety_controller k_position="50" k_velocity="10" soft_lower_limit="-0.84" soft_upper_limit="0.84"/>-->
  </joint>
  <!-- Extensions -->
  <transmission name="L0_hip_tran">
    <type>transmission_interface/SimpleTransmission</type>
    <joint name="L0_hip_joint">
      <!--<hardwareInterface>hardware_interface/EffortJointInterface</hardwareInterface>-->
      <hardwareInterface>EffortJointInterface</hardwareInterface>
    </joint>
    <actuator name="L0_hip_motor">
      <!--<hardwareInterface>hardware_interface/EffortJointInterface</hardwareInterface>-->
      <mechanicalReduction>1</mechanicalReduction>
    </actuator>
  </transmission>
  <!-- Upper leg joint -->
  <joint name="L0_upper_joint" type="revolute">
    <parent link="L0_hipassembly"/>
    <child link="L0_upperleg"/>
    <axis xyz="0 1 0"/>
    <origin rpy="0 4.7124 0" xyz="0 0 -0.084982"/>
    <limit effort="500.0" lower="1.96405" upper="5.78886" velocity="12.0"/>
    <dynamics damping="0.1" friction="0.1"/>
    <!--<safety_controller k_position="50" k_velocity="10" soft_lower_limit="1.96405" soft_upper_limit="5.78886"/>-->
  </joint>
  <!-- Extensions -->
  <transmission name="L0_upper_tran">
    <type>transmission_interface/SimpleTransmission</type>
    <joint name="L0_upper_joint">
      <!--<hardwareInterface>hardware_interface/EffortJointInterface</hardwareInterface>-->
      <hardwareInterface>EffortJointInterface</hardwareInterface>
    </joint>
    <actuator name="L0_upper_motor">
      <!--<hardwareInterface>hardware_interface/EffortJointInterface</hardwareInterface>-->
      <mechanicalReduction>1</mechanicalReduction>
    </actuator>
  </transmission>
  <!-- Lower leg joint -->
  <joint name="L0_lower_joint" type="revolute">
    <parent link="L0_upperleg"/>
    <child link="L0_lowerleg"/>
    <axis xyz="0 1 0"/>
    <origin rpy="0 0 0" xyz="-0.300656 0 0"/>
    <limit effort="500.0" lower="-2.600884" upper="2.600884" velocity="12.0"/>
    <dynamics damping="0.1" friction="0.1"/>
    <!--<safety_controller k_position="50" k_velocity="10" soft_lower_limit="-2.600884" soft_upper_limit="2.600884"/>-->
  </joint>
  <!-- Extensions -->
  <transmission name="L0_lower_tran">
    <type>transmission_interface/SimpleTransmission</type>
    <joint name="L0_lower_joint">
      <!--<hardwareInterface>hardware_interface/EffortJointInterface</hardwareInterface>-->
      <hardwareInterface>EffortJointInterface</hardwareInterface>
    </joint>
    <actuator name="L0_lower_motor">
      <!--<hardwareInterface>hardware_interface/EffortJointInterface</hardwareInterface>-->
      <mechanicalReduction>1</mechanicalReduction>
    </actuator>
  </transmission>
  <!-- Foot joint -->
  <joint name="L0_foot_joint" type="fixed">
    <origin rpy="0 0 0" xyz="-0.283335 0 0"/>
    <parent link="L0_lowerleg"/>
    <child link="L0_foot"/>
  </joint>
  <!-- Links -->
  <!-- Hip assembly link -->
  <link name="L0_hipassembly">
    <inertial>
      <origin xyz="-0.02923 0. -0.0271748"/>
      <mass value="1.0"/>
      <inertia ixx="0.00871" ixy="-0.000001" ixz="-0.000001" iyy="0.00301" iyz="0.000002" izz="0.00871"/>
    </inertial>
    <visual>
      <geometry>
        <mesh filename="/home/dada/mujoco/qz2_urdf/qz2_meshes/r1.STL" scale="0.001 0.001 0.001"/>
      </geometry>
      <origin rpy="1.570795 0 1.570795" xyz="-0.050293 0 0"/>
      <material name="grey">
        <color rgba="1.0 1.0 1.0 0.3"/>
      </material>
    </visual>
    <collision>
      <geometry>
        <mesh filename="/home/dada/mujoco/qz2_urdf/qz2_meshes/r1.STL" scale="0.001 0.001 0.001"/>
      </geometry>
      <origin rpy="1.570795 0 1.570795" xyz="-0.050293 0 0"/>
    </collision>
  </link>
  <!-- Upper leg link -->
  <link name="L0_upperleg">
    <inertial>
      <origin xyz="-0.115692 0. 0."/>
      <mass value="0.9"/>
      <inertia ixx="0.00188" ixy="0.000002" ixz="-0.000001" iyy="0.01519" iyz="-0.000002" izz="0.01511"/>
    </inertial>
    <visual>
      <geometry>
        <mesh filename="/home/dada/mujoco/qz2_urdf/qz2_meshes/upperLeg.STL" scale="0.001 0.001 0.001"/>
      </geometry>
      <origin rpy="-1.570795 0 1.570795" xyz="0 0 0"/>
      <material name="grey">
        <color rgba="1.0 1.0 1.0 0.3"/>
      </material>
    </visual>
    <collision>
      <geometry>
        <mesh filename="/home/dada/mujoco/qz2_urdf/qz2_meshes/upperLeg.STL" scale="0.001 0.001 0.001"/>
      </geometry>
      <origin rpy="-1.570795 0 1.570795" xyz="0 0 0"/>
    </collision>
  </link>
  <!-- Extensions -->
  <!-- Lower leg link -->
  <link name="L0_lowerleg">
    <inertial>
      <!-- <origin xyz="-0.000000799 0.000008540 0.124197800"/> -->
      <origin xyz="-0.124198 0.0 0.0"/>
      <mass value="0.7"/>
      <inertia ixx="0.00037" ixy="0.000001" ixz="-0.000006" iyy="0.008233" iyz="0.0" izz="0.008256"/>
    </inertial>
    <visual>
      <geometry>
        <mesh filename="/home/dada/mujoco/qz2_urdf/qz2_meshes/lowerLeg.STL" scale="0.001 0.001 0.001"/>
      </geometry>
      <origin rpy="-1.570795 0 1.570795" xyz="0 0 0"/>
      <material name="grey">
        <color rgba="1.0 1.0 1.0 0.3"/>
      </material>
    </visual>
    <collision>
      <geometry>
        <mesh filename="/home/dada/mujoco/qz2_urdf/qz2_meshes/lowerLeg.STL" scale="0.001 0.001 0.001"/>
      </geometry>
      <origin rpy="-1.570795 0 1.570795" xyz="0 0 0"/>
    </collision>
  </link>
  <!-- Extensions -->
  <!-- Foot link -->
  <link name="L0_foot">
    <visual>
      <geometry>
        <mesh filename="/home/dada/mujoco/qz2_urdf/qz2_meshes/tip.STL" scale="0.001 0.001 0.001"/>
      </geometry>
      <origin rpy="0 -1.570795 0" xyz="0 0 0"/>
      <material name="endgrey">
        <color rgba="1.0 1.0 1.0 0.6"/>
      </material>
    </visual>
    <collision>
      <origin rpy="0 -1.570795 0" xyz="0 0 0"/>
      <geometry>
        <mesh filename="/home/dada/mujoco/qz2_urdf/qz2_meshes/tip.STL" scale="0.001 0.001 0.001"/>
      </geometry>
    </collision>
  </link>
  <!-- Extensions -->
  <!-- Joints -->
  <!-- Hip assembly joint -->
  <joint name="L1_hip_joint" type="revolute">
    <parent link="base"/>
    <child link="L1_hipassembly"/>
    <axis xyz="1 0 0"/>
    <origin rpy="0 0 0" xyz="0.254043 -0.215 0"/>
    <limit effort="500.0" lower="-0.84" upper="0.84" velocity="12.0"/>
    <dynamics damping="0.1" friction="0.1"/>
    <!--<safety_controller k_position="50" k_velocity="10" soft_lower_limit="-0.84" soft_upper_limit="0.84"/>-->
  </joint>
  <!-- Extensions -->
  <transmission name="L1_hip_tran">
    <type>transmission_interface/SimpleTransmission</type>
    <joint name="L1_hip_joint">
      <!--<hardwareInterface>hardware_interface/EffortJointInterface</hardwareInterface>-->
      <hardwareInterface>EffortJointInterface</hardwareInterface>
    </joint>
    <actuator name="L1_hip_motor">
      <!--<hardwareInterface>hardware_interface/EffortJointInterface</hardwareInterface>-->
      <mechanicalReduction>1</mechanicalReduction>
    </actuator>
  </transmission>
  <!-- Upper leg joint -->
  <joint name="L1_upper_joint" type="revolute">
    <parent link="L1_hipassembly"/>
    <child link="L1_upperleg"/>
    <axis xyz="0 1 0"/>
    <origin rpy="0 4.7124 0" xyz="0 0 -0.084982"/>
    <limit effort="500.0" lower="1.96405" upper="5.78886" velocity="12.0"/>
    <dynamics damping="0.1" friction="0.1"/>
    <!--<safety_controller k_position="50" k_velocity="10" soft_lower_limit="1.96405" soft_upper_limit="5.78886"/>-->
  </joint>
  <!-- Extensions -->
  <transmission name="L1_upper_tran">
    <type>transmission_interface/SimpleTransmission</type>
    <joint name="L1_upper_joint">
      <!--<hardwareInterface>hardware_interface/EffortJointInterface</hardwareInterface>-->
      <hardwareInterface>EffortJointInterface</hardwareInterface>
    </joint>
    <actuator name="L1_upper_motor">
      <!--<hardwareInterface>hardware_interface/EffortJointInterface</hardwareInterface>-->
      <mechanicalReduction>1</mechanicalReduction>
    </actuator>
  </transmission>
  <!-- Lower leg joint -->
  <joint name="L1_lower_joint" type="revolute">
    <parent link="L1_upperleg"/>
    <child link="L1_lowerleg"/>
    <axis xyz="0 1 0"/>
    <origin rpy="0 0 0" xyz="-0.300656 0 0"/>
    <limit effort="500.0" lower="-2.600884" upper="2.600884" velocity="12.0"/>
    <dynamics damping="0.1" friction="0.1"/>
    <!--<safety_controller k_position="50" k_velocity="10" soft_lower_limit="-2.600884" soft_upper_limit="2.600884"/>-->
  </joint>
  <!-- Extensions -->
  <transmission name="L1_lower_tran">
    <type>transmission_interface/SimpleTransmission</type>
    <joint name="L1_lower_joint">
      <!--<hardwareInterface>hardware_interface/EffortJointInterface</hardwareInterface>-->
      <hardwareInterface>EffortJointInterface</hardwareInterface>
    </joint>
    <actuator name="L1_lower_motor">
      <!--<hardwareInterface>hardware_interface/EffortJointInterface</hardwareInterface>-->
      <mechanicalReduction>1</mechanicalReduction>
    </actuator>
  </transmission>
  <!-- Foot joint -->
  <joint name="L1_foot_joint" type="fixed">
    <origin rpy="0 0 0" xyz="-0.283335 0 0"/>
    <parent link="L1_lowerleg"/>
    <child link="L1_foot"/>
  </joint>
  <!-- Links -->
  <!-- Hip assembly link -->
  <link name="L1_hipassembly">
    <inertial>
      <origin xyz="-0.02923 0. -0.0271748"/>
      <mass value="1.0"/>
      <inertia ixx="0.00871" ixy="-0.000001" ixz="-0.000001" iyy="0.00301" iyz="0.000002" izz="0.00871"/>
    </inertial>
    <visual>
      <geometry>
        <mesh filename="/home/dada/mujoco/qz2_urdf/qz2_meshes/r1.STL" scale="0.001 0.001 0.001"/>
      </geometry>
      <origin rpy="1.570795 0 1.570795" xyz="-0.050293 0 0"/>
      <material name="grey">
        <color rgba="1.0 1.0 1.0 0.3"/>
      </material>
    </visual>
    <collision>
      <geometry>
        <mesh filename="/home/dada/mujoco/qz2_urdf/qz2_meshes/r1.STL" scale="0.001 0.001 0.001"/>
      </geometry>
      <origin rpy="1.570795 0 1.570795" xyz="-0.050293 0 0"/>
    </collision>
  </link>
  <!-- Upper leg link -->
  <link name="L1_upperleg">
    <inertial>
      <origin xyz="-0.115692 0. 0."/>
      <mass value="0.9"/>
      <inertia ixx="0.00188" ixy="0.000002" ixz="-0.000001" iyy="0.01519" iyz="-0.000002" izz="0.01511"/>
    </inertial>
    <visual>
      <geometry>
        <mesh filename="/home/dada/mujoco/qz2_urdf/qz2_meshes/upperLeg.STL" scale="0.001 0.001 0.001"/>
      </geometry>
      <origin rpy="-1.570795 0 1.570795" xyz="0 0 0"/>
      <material name="grey">
        <color rgba="1.0 1.0 1.0 0.3"/>
      </material>
    </visual>
    <collision>
      <geometry>
        <mesh filename="/home/dada/mujoco/qz2_urdf/qz2_meshes/upperLeg.STL" scale="0.001 0.001 0.001"/>
      </geometry>
      <origin rpy="-1.570795 0 1.570795" xyz="0 0 0"/>
    </collision>
  </link>
  <!-- Extensions -->
  <!-- Lower leg link -->
  <link name="L1_lowerleg">
    <inertial>
      <!-- <origin xyz="-0.000000799 0.000008540 0.124197800"/> -->
      <origin xyz="-0.124198 0.0 0.0"/>
      <mass value="0.7"/>
      <inertia ixx="0.00037" ixy="0.000001" ixz="-0.000006" iyy="0.008233" iyz="0.0" izz="0.008256"/>
    </inertial>
    <visual>
      <geometry>
        <mesh filename="/home/dada/mujoco/qz2_urdf/qz2_meshes/lowerLeg.STL" scale="0.001 0.001 0.001"/>
      </geometry>
      <origin rpy="-1.570795 0 1.570795" xyz="0 0 0"/>
      <material name="grey">
        <color rgba="1.0 1.0 1.0 0.3"/>
      </material>
    </visual>
    <collision>
      <geometry>
        <mesh filename="/home/dada/mujoco/qz2_urdf/qz2_meshes/lowerLeg.STL" scale="0.001 0.001 0.001"/>
      </geometry>
      <origin rpy="-1.570795 0 1.570795" xyz="0 0 0"/>
    </collision>
  </link>
  <!-- Extensions -->
  <!-- Foot link -->
  <link name="L1_foot">
    <visual>
      <geometry>
        <mesh filename="/home/dada/mujoco/qz2_urdf/qz2_meshes/tip.STL" scale="0.001 0.001 0.001"/>
      </geometry>
      <origin rpy="0 -1.570795 0" xyz="0 0 0"/>
      <material name="endgrey">
        <color rgba="1.0 1.0 1.0 0.6"/>
      </material>
    </visual>
    <collision>
      <origin rpy="0 -1.570795 0" xyz="0 0 0"/>
      <geometry>
        <mesh filename="/home/dada/mujoco/qz2_urdf/qz2_meshes/tip.STL" scale="0.001 0.001 0.001"/>
      </geometry>
    </collision>
  </link>
  <!-- Extensions -->
  <!-- Joints -->
  <!-- Hip assembly joint -->
  <joint name="L2_hip_joint" type="revolute">
    <parent link="base"/>
    <child link="L2_hipassembly"/>
    <axis xyz="1 0 0"/>
    <origin rpy="0 0 3.14159" xyz="-0.254043 -0.215 0"/>
    <limit effort="500.0" lower="-0.84" upper="0.84" velocity="12.0"/>
    <dynamics damping="0.1" friction="0.1"/>
    <!--<safety_controller k_position="50" k_velocity="10" soft_lower_limit="-0.84" soft_upper_limit="0.84"/>-->
  </joint>
  <!-- Extensions -->
  <transmission name="L2_hip_tran">
    <type>transmission_interface/SimpleTransmission</type>
    <joint name="L2_hip_joint">
      <!--<hardwareInterface>hardware_interface/EffortJointInterface</hardwareInterface>-->
      <hardwareInterface>EffortJointInterface</hardwareInterface>
    </joint>
    <actuator name="L2_hip_motor">
      <!--<hardwareInterface>hardware_interface/EffortJointInterface</hardwareInterface>-->
      <mechanicalReduction>1</mechanicalReduction>
    </actuator>
  </transmission>
  <!-- Upper leg joint -->
  <joint name="L2_upper_joint" type="revolute">
    <parent link="L2_hipassembly"/>
    <child link="L2_upperleg"/>
    <axis xyz="0 1 0"/>
    <origin rpy="0 4.7124 0" xyz="0 0 -0.084982"/>
    <limit effort="500.0" lower="1.96405" upper="5.78886" velocity="12.0"/>
    <dynamics damping="0.1" friction="0.1"/>
    <!--<safety_controller k_position="50" k_velocity="10" soft_lower_limit="1.96405" soft_upper_limit="5.78886"/>-->
  </joint>
  <!-- Extensions -->
  <transmission name="L2_upper_tran">
    <type>transmission_interface/SimpleTransmission</type>
    <joint name="L2_upper_joint">
      <!--<hardwareInterface>hardware_interface/EffortJointInterface</hardwareInterface>-->
      <hardwareInterface>EffortJointInterface</hardwareInterface>
    </joint>
    <actuator name="L2_upper_motor">
      <!--<hardwareInterface>hardware_interface/EffortJointInterface</hardwareInterface>-->
      <mechanicalReduction>1</mechanicalReduction>
    </actuator>
  </transmission>
  <!-- Lower leg joint -->
  <joint name="L2_lower_joint" type="revolute">
    <parent link="L2_upperleg"/>
    <child link="L2_lowerleg"/>
    <axis xyz="0 1 0"/>
    <origin rpy="0 0 0" xyz="-0.300656 0 0"/>
    <limit effort="500.0" lower="-2.600884" upper="2.600884" velocity="12.0"/>
    <dynamics damping="0.1" friction="0.1"/>
    <!--<safety_controller k_position="50" k_velocity="10" soft_lower_limit="-2.600884" soft_upper_limit="2.600884"/>-->
  </joint>
  <!-- Extensions -->
  <transmission name="L2_lower_tran">
    <type>transmission_interface/SimpleTransmission</type>
    <joint name="L2_lower_joint">
      <!--<hardwareInterface>hardware_interface/EffortJointInterface</hardwareInterface>-->
      <hardwareInterface>EffortJointInterface</hardwareInterface>
    </joint>
    <actuator name="L2_lower_motor">
      <!--<hardwareInterface>hardware_interface/EffortJointInterface</hardwareInterface>-->
      <mechanicalReduction>1</mechanicalReduction>
    </actuator>
  </transmission>
  <!-- Foot joint -->
  <joint name="L2_foot_joint" type="fixed">
    <origin rpy="0 0 0" xyz="-0.283335 0 0"/>
    <parent link="L2_lowerleg"/>
    <child link="L2_foot"/>
  </joint>
  <!-- Links -->
  <!-- Hip assembly link -->
  <link name="L2_hipassembly">
    <inertial>
      <origin xyz="-0.02923 0. -0.0271748"/>
      <mass value="1.0"/>
      <inertia ixx="0.00871" ixy="-0.000001" ixz="-0.000001" iyy="0.00301" iyz="0.000002" izz="0.00871"/>
    </inertial>
    <visual>
      <geometry>
        <mesh filename="/home/dada/mujoco/qz2_urdf/qz2_meshes/r1.STL" scale="0.001 0.001 0.001"/>
      </geometry>
      <origin rpy="1.570795 0 1.570795" xyz="-0.050293 0 0"/>
      <material name="grey">
        <color rgba="1.0 1.0 1.0 0.3"/>
      </material>
    </visual>
    <collision>
      <geometry>
        <mesh filename="/home/dada/mujoco/qz2_urdf/qz2_meshes/r1.STL" scale="0.001 0.001 0.001"/>
      </geometry>
      <origin rpy="1.570795 0 1.570795" xyz="-0.050293 0 0"/>
    </collision>
  </link>
  <!-- Upper leg link -->
  <link name="L2_upperleg">
    <inertial>
      <origin xyz="-0.115692 0. 0."/>
      <mass value="0.9"/>
      <inertia ixx="0.00188" ixy="0.000002" ixz="-0.000001" iyy="0.01519" iyz="-0.000002" izz="0.01511"/>
    </inertial>
    <visual>
      <geometry>
        <mesh filename="/home/dada/mujoco/qz2_urdf/qz2_meshes/upperLeg.STL" scale="0.001 0.001 0.001"/>
      </geometry>
      <origin rpy="-1.570795 0 1.570795" xyz="0 0 0"/>
      <material name="grey">
        <color rgba="1.0 1.0 1.0 0.3"/>
      </material>
    </visual>
    <collision>
      <geometry>
        <mesh filename="/home/dada/mujoco/qz2_urdf/qz2_meshes/upperLeg.STL" scale="0.001 0.001 0.001"/>
      </geometry>
      <origin rpy="-1.570795 0 1.570795" xyz="0 0 0"/>
    </collision>
  </link>
  <!-- Extensions -->
  <!-- Lower leg link -->
  <link name="L2_lowerleg">
    <inertial>
      <!-- <origin xyz="-0.000000799 0.000008540 0.124197800"/> -->
      <origin xyz="-0.124198 0.0 0.0"/>
      <mass value="0.7"/>
      <inertia ixx="0.00037" ixy="0.000001" ixz="-0.000006" iyy="0.008233" iyz="0.0" izz="0.008256"/>
    </inertial>
    <visual>
      <geometry>
        <mesh filename="/home/dada/mujoco/qz2_urdf/qz2_meshes/lowerLeg.STL" scale="0.001 0.001 0.001"/>
      </geometry>
      <origin rpy="-1.570795 0 1.570795" xyz="0 0 0"/>
      <material name="grey">
        <color rgba="1.0 1.0 1.0 0.3"/>
      </material>
    </visual>
    <collision>
      <geometry>
        <mesh filename="/home/dada/mujoco/qz2_urdf/qz2_meshes/lowerLeg.STL" scale="0.001 0.001 0.001"/>
      </geometry>
      <origin rpy="-1.570795 0 1.570795" xyz="0 0 0"/>
    </collision>
  </link>
  <!-- Extensions -->
  <!-- Foot link -->
  <link name="L2_foot">
    <visual>
      <geometry>
        <mesh filename="/home/dada/mujoco/qz2_urdf/qz2_meshes/tip.STL" scale="0.001 0.001 0.001"/>
      </geometry>
      <origin rpy="0 -1.570795 0" xyz="0 0 0"/>
      <material name="endgrey">
        <color rgba="1.0 1.0 1.0 0.6"/>
      </material>
    </visual>
    <collision>
      <origin rpy="0 -1.570795 0" xyz="0 0 0"/>
      <geometry>
        <mesh filename="/home/dada/mujoco/qz2_urdf/qz2_meshes/tip.STL" scale="0.001 0.001 0.001"/>
      </geometry>
    </collision>
  </link>
  <!-- Extensions -->
  <!-- Joints -->
  <!-- Hip assembly joint -->
  <joint name="L3_hip_joint" type="revolute">
    <parent link="base"/>
    <child link="L3_hipassembly"/>
    <axis xyz="1 0 0"/>
    <origin rpy="0 0 3.14159" xyz="-0.510043 0 0"/>
    <limit effort="500.0" lower="-0.84" upper="0.84" velocity="12.0"/>
    <dynamics damping="0.1" friction="0.1"/>
    <!--<safety_controller k_position="50" k_velocity="10" soft_lower_limit="-0.84" soft_upper_limit="0.84"/>-->
  </joint>
  <!-- Extensions -->
  <transmission name="L3_hip_tran">
    <type>transmission_interface/SimpleTransmission</type>
    <joint name="L3_hip_joint">
      <!--<hardwareInterface>hardware_interface/EffortJointInterface</hardwareInterface>-->
      <hardwareInterface>EffortJointInterface</hardwareInterface>
    </joint>
    <actuator name="L3_hip_motor">
      <!--<hardwareInterface>hardware_interface/EffortJointInterface</hardwareInterface>-->
      <mechanicalReduction>1</mechanicalReduction>
    </actuator>
  </transmission>
  <!-- Upper leg joint -->
  <joint name="L3_upper_joint" type="revolute">
    <parent link="L3_hipassembly"/>
    <child link="L3_upperleg"/>
    <axis xyz="0 1 0"/>
    <origin rpy="0 4.7124 0" xyz="0 0 -0.084982"/>
    <limit effort="500.0" lower="1.96405" upper="5.78886" velocity="12.0"/>
    <dynamics damping="0.1" friction="0.1"/>
    <!--<safety_controller k_position="50" k_velocity="10" soft_lower_limit="1.96405" soft_upper_limit="5.78886"/>-->
  </joint>
  <!-- Extensions -->
  <transmission name="L3_upper_tran">
    <type>transmission_interface/SimpleTransmission</type>
    <joint name="L3_upper_joint">
      <!--<hardwareInterface>hardware_interface/EffortJointInterface</hardwareInterface>-->
      <hardwareInterface>EffortJointInterface</hardwareInterface>
    </joint>
    <actuator name="L3_upper_motor">
      <!--<hardwareInterface>hardware_interface/EffortJointInterface</hardwareInterface>-->
      <mechanicalReduction>1</mechanicalReduction>
    </actuator>
  </transmission>
  <!-- Lower leg joint -->
  <joint name="L3_lower_joint" type="revolute">
    <parent link="L3_upperleg"/>
    <child link="L3_lowerleg"/>
    <axis xyz="0 1 0"/>
    <origin rpy="0 0 0" xyz="-0.300656 0 0"/>
    <limit effort="500.0" lower="-2.600884" upper="2.600884" velocity="12.0"/>
    <dynamics damping="0.1" friction="0.1"/>
    <!--<safety_controller k_position="50" k_velocity="10" soft_lower_limit="-2.600884" soft_upper_limit="2.600884"/>-->
  </joint>
  <!-- Extensions -->
  <transmission name="L3_lower_tran">
    <type>transmission_interface/SimpleTransmission</type>
    <joint name="L3_lower_joint">
      <!--<hardwareInterface>hardware_interface/EffortJointInterface</hardwareInterface>-->
      <hardwareInterface>EffortJointInterface</hardwareInterface>
    </joint>
    <actuator name="L3_lower_motor">
      <!--<hardwareInterface>hardware_interface/EffortJointInterface</hardwareInterface>-->
      <mechanicalReduction>1</mechanicalReduction>
    </actuator>
  </transmission>
  <!-- Foot joint -->
  <joint name="L3_foot_joint" type="fixed">
    <origin rpy="0 0 0" xyz="-0.283335 0 0"/>
    <parent link="L3_lowerleg"/>
    <child link="L3_foot"/>
  </joint>
  <!-- Links -->
  <!-- Hip assembly link -->
  <link name="L3_hipassembly">
    <inertial>
      <origin xyz="-0.02923 0. -0.0271748"/>
      <mass value="1.0"/>
      <inertia ixx="0.00871" ixy="-0.000001" ixz="-0.000001" iyy="0.00301" iyz="0.000002" izz="0.00871"/>
    </inertial>
    <visual>
      <geometry>
        <mesh filename="/home/dada/mujoco/qz2_urdf/qz2_meshes/r1.STL" scale="0.001 0.001 0.001"/>
      </geometry>
      <origin rpy="1.570795 0 1.570795" xyz="-0.050293 0 0"/>
      <material name="grey">
        <color rgba="1.0 1.0 1.0 0.3"/>
      </material>
    </visual>
    <collision>
      <geometry>
        <mesh filename="/home/dada/mujoco/qz2_urdf/qz2_meshes/r1.STL" scale="0.001 0.001 0.001"/>
      </geometry>
      <origin rpy="1.570795 0 1.570795" xyz="-0.050293 0 0"/>
    </collision>
  </link>
  <!-- Upper leg link -->
  <link name="L3_upperleg">
    <inertial>
      <origin xyz="-0.115692 0. 0."/>
      <mass value="0.9"/>
      <inertia ixx="0.00188" ixy="0.000002" ixz="-0.000001" iyy="0.01519" iyz="-0.000002" izz="0.01511"/>
    </inertial>
    <visual>
      <geometry>
        <mesh filename="/home/dada/mujoco/qz2_urdf/qz2_meshes/upperLeg.STL" scale="0.001 0.001 0.001"/>
      </geometry>
      <origin rpy="-1.570795 0 1.570795" xyz="0 0 0"/>
      <material name="grey">
        <color rgba="1.0 1.0 1.0 0.3"/>
      </material>
    </visual>
    <collision>
      <geometry>
        <mesh filename="/home/dada/mujoco/qz2_urdf/qz2_meshes/upperLeg.STL" scale="0.001 0.001 0.001"/>
      </geometry>
      <origin rpy="-1.570795 0 1.570795" xyz="0 0 0"/>
    </collision>
  </link>
  <!-- Extensions -->
  <!-- Lower leg link -->
  <link name="L3_lowerleg">
    <inertial>
      <!-- <origin xyz="-0.000000799 0.000008540 0.124197800"/> -->
      <origin xyz="-0.124198 0.0 0.0"/>
      <mass value="0.7"/>
      <inertia ixx="0.00037" ixy="0.000001" ixz="-0.000006" iyy="0.008233" iyz="0.0" izz="0.008256"/>
    </inertial>
    <visual>
      <geometry>
        <mesh filename="/home/dada/mujoco/qz2_urdf/qz2_meshes/lowerLeg.STL" scale="0.001 0.001 0.001"/>
      </geometry>
      <origin rpy="-1.570795 0 1.570795" xyz="0 0 0"/>
      <material name="grey">
        <color rgba="1.0 1.0 1.0 0.3"/>
      </material>
    </visual>
    <collision>
      <geometry>
        <mesh filename="/home/dada/mujoco/qz2_urdf/qz2_meshes/lowerLeg.STL" scale="0.001 0.001 0.001"/>
      </geometry>
      <origin rpy="-1.570795 0 1.570795" xyz="0 0 0"/>
    </collision>
  </link>
  <!-- Extensions -->
  <!-- Foot link -->
  <link name="L3_foot">
    <visual>
      <geometry>
        <mesh filename="/home/dada/mujoco/qz2_urdf/qz2_meshes/tip.STL" scale="0.001 0.001 0.001"/>
      </geometry>
      <origin rpy="0 -1.570795 0" xyz="0 0 0"/>
      <material name="endgrey">
        <color rgba="1.0 1.0 1.0 0.6"/>
      </material>
    </visual>
    <collision>
      <origin rpy="0 -1.570795 0" xyz="0 0 0"/>
      <geometry>
        <mesh filename="/home/dada/mujoco/qz2_urdf/qz2_meshes/tip.STL" scale="0.001 0.001 0.001"/>
      </geometry>
    </collision>
  </link>
  <!-- Extensions -->
  <!-- Joints -->
  <!-- Hip assembly joint -->
  <joint name="L4_hip_joint" type="revolute">
    <parent link="base"/>
    <child link="L4_hipassembly"/>
    <axis xyz="1 0 0"/>
    <origin rpy="0 0 3.14159" xyz="-0.254043 0.215 0"/>
    <limit effort="500.0" lower="-0.84" upper="0.84" velocity="12.0"/>
    <dynamics damping="0.1" friction="0.1"/>
    <!--<safety_controller k_position="50" k_velocity="10" soft_lower_limit="-0.84" soft_upper_limit="0.84"/>-->
  </joint>
  <!-- Extensions -->
  <transmission name="L4_hip_tran">
    <type>transmission_interface/SimpleTransmission</type>
    <joint name="L4_hip_joint">
      <!--<hardwareInterface>hardware_interface/EffortJointInterface</hardwareInterface>-->
      <hardwareInterface>EffortJointInterface</hardwareInterface>
    </joint>
    <actuator name="L4_hip_motor">
      <!--<hardwareInterface>hardware_interface/EffortJointInterface</hardwareInterface>-->
      <mechanicalReduction>1</mechanicalReduction>
    </actuator>
  </transmission>
  <!-- Upper leg joint -->
  <joint name="L4_upper_joint" type="revolute">
    <parent link="L4_hipassembly"/>
    <child link="L4_upperleg"/>
    <axis xyz="0 1 0"/>
    <origin rpy="0 4.7124 0" xyz="0 0 -0.084982"/>
    <limit effort="500.0" lower="1.96405" upper="5.78886" velocity="12.0"/>
    <dynamics damping="0.1" friction="0.1"/>
    <!--<safety_controller k_position="50" k_velocity="10" soft_lower_limit="1.96405" soft_upper_limit="5.78886"/>-->
  </joint>
  <!-- Extensions -->
  <transmission name="L4_upper_tran">
    <type>transmission_interface/SimpleTransmission</type>
    <joint name="L4_upper_joint">
      <!--<hardwareInterface>hardware_interface/EffortJointInterface</hardwareInterface>-->
      <hardwareInterface>EffortJointInterface</hardwareInterface>
    </joint>
    <actuator name="L4_upper_motor">
      <!--<hardwareInterface>hardware_interface/EffortJointInterface</hardwareInterface>-->
      <mechanicalReduction>1</mechanicalReduction>
    </actuator>
  </transmission>
  <!-- Lower leg joint -->
  <joint name="L4_lower_joint" type="revolute">
    <parent link="L4_upperleg"/>
    <child link="L4_lowerleg"/>
    <axis xyz="0 1 0"/>
    <origin rpy="0 0 0" xyz="-0.300656 0 0"/>
    <limit effort="500.0" lower="-2.600884" upper="2.600884" velocity="12.0"/>
    <dynamics damping="0.1" friction="0.1"/>
    <!--<safety_controller k_position="50" k_velocity="10" soft_lower_limit="-2.600884" soft_upper_limit="2.600884"/>-->
  </joint>
  <!-- Extensions -->
  <transmission name="L4_lower_tran">
    <type>transmission_interface/SimpleTransmission</type>
    <joint name="L4_lower_joint">
      <!--<hardwareInterface>hardware_interface/EffortJointInterface</hardwareInterface>-->
      <hardwareInterface>EffortJointInterface</hardwareInterface>
    </joint>
    <actuator name="L4_lower_motor">
      <!--<hardwareInterface>hardware_interface/EffortJointInterface</hardwareInterface>-->
      <mechanicalReduction>1</mechanicalReduction>
    </actuator>
  </transmission>
  <!-- Foot joint -->
  <joint name="L4_foot_joint" type="fixed">
    <origin rpy="0 0 0" xyz="-0.283335 0 0"/>
    <parent link="L4_lowerleg"/>
    <child link="L4_foot"/>
  </joint>
  <!-- Links -->
  <!-- Hip assembly link -->
  <link name="L4_hipassembly">
    <inertial>
      <origin xyz="-0.02923 0. -0.0271748"/>
      <mass value="1.0"/>
      <inertia ixx="0.00871" ixy="-0.000001" ixz="-0.000001" iyy="0.00301" iyz="0.000002" izz="0.00871"/>
    </inertial>
    <visual>
      <geometry>
        <mesh filename="/home/dada/mujoco/qz2_urdf/qz2_meshes/r1.STL" scale="0.001 0.001 0.001"/>
      </geometry>
      <origin rpy="1.570795 0 1.570795" xyz="-0.050293 0 0"/>
      <material name="grey">
        <color rgba="1.0 1.0 1.0 0.3"/>
      </material>
    </visual>
    <collision>
      <geometry>
        <mesh filename="/home/dada/mujoco/qz2_urdf/qz2_meshes/r1.STL" scale="0.001 0.001 0.001"/>
      </geometry>
      <origin rpy="1.570795 0 1.570795" xyz="-0.050293 0 0"/>
    </collision>
  </link>
  <!-- Upper leg link -->
  <link name="L4_upperleg">
    <inertial>
      <origin xyz="-0.115692 0. 0."/>
      <mass value="0.9"/>
      <inertia ixx="0.00188" ixy="0.000002" ixz="-0.000001" iyy="0.01519" iyz="-0.000002" izz="0.01511"/>
    </inertial>
    <visual>
      <geometry>
        <mesh filename="/home/dada/mujoco/qz2_urdf/qz2_meshes/upperLeg.STL" scale="0.001 0.001 0.001"/>
      </geometry>
      <origin rpy="-1.570795 0 1.570795" xyz="0 0 0"/>
      <material name="grey">
        <color rgba="1.0 1.0 1.0 0.3"/>
      </material>
    </visual>
    <collision>
      <geometry>
        <mesh filename="/home/dada/mujoco/qz2_urdf/qz2_meshes/upperLeg.STL" scale="0.001 0.001 0.001"/>
      </geometry>
      <origin rpy="-1.570795 0 1.570795" xyz="0 0 0"/>
    </collision>
  </link>
  <!-- Extensions -->
  <!-- Lower leg link -->
  <link name="L4_lowerleg">
    <inertial>
      <!-- <origin xyz="-0.000000799 0.000008540 0.124197800"/> -->
      <origin xyz="-0.124198 0.0 0.0"/>
      <mass value="0.7"/>
      <inertia ixx="0.00037" ixy="0.000001" ixz="-0.000006" iyy="0.008233" iyz="0.0" izz="0.008256"/>
    </inertial>
    <visual>
      <geometry>
        <mesh filename="/home/dada/mujoco/qz2_urdf/qz2_meshes/lowerLeg.STL" scale="0.001 0.001 0.001"/>
      </geometry>
      <origin rpy="-1.570795 0 1.570795" xyz="0 0 0"/>
      <material name="grey">
        <color rgba="1.0 1.0 1.0 0.3"/>
      </material>
    </visual>
    <collision>
      <geometry>
        <mesh filename="/home/dada/mujoco/qz2_urdf/qz2_meshes/lowerLeg.STL" scale="0.001 0.001 0.001"/>
      </geometry>
      <origin rpy="-1.570795 0 1.570795" xyz="0 0 0"/>
    </collision>
  </link>
  <!-- Extensions -->
  <!-- Foot link -->
  <link name="L4_foot">
    <visual>
      <geometry>
        <mesh filename="/home/dada/mujoco/qz2_urdf/qz2_meshes/tip.STL" scale="0.001 0.001 0.001"/>
      </geometry>
      <origin rpy="0 -1.570795 0" xyz="0 0 0"/>
      <material name="endgrey">
        <color rgba="1.0 1.0 1.0 0.6"/>
      </material>
    </visual>
    <collision>
      <origin rpy="0 -1.570795 0" xyz="0 0 0"/>
      <geometry>
        <mesh filename="/home/dada/mujoco/qz2_urdf/qz2_meshes/tip.STL" scale="0.001 0.001 0.001"/>
      </geometry>
    </collision>
  </link>
  <!-- Extensions -->
  <!-- Joints -->
  <!-- Hip assembly joint -->
  <joint name="L5_hip_joint" type="revolute">
    <parent link="base"/>
    <child link="L5_hipassembly"/>
    <axis xyz="1 0 0"/>
    <origin rpy="0 0 0" xyz="0.254043 0.215 0"/>
    <limit effort="500.0" lower="-0.84" upper="0.84" velocity="12.0"/>
    <dynamics damping="0.1" friction="0.1"/>
    <!--<safety_controller k_position="50" k_velocity="10" soft_lower_limit="-0.84" soft_upper_limit="0.84"/>-->
  </joint>
  <!-- Extensions -->
  <transmission name="L5_hip_tran">
    <type>transmission_interface/SimpleTransmission</type>
    <joint name="L5_hip_joint">
      <!--<hardwareInterface>hardware_interface/EffortJointInterface</hardwareInterface>-->
      <hardwareInterface>EffortJointInterface</hardwareInterface>
    </joint>
    <actuator name="L5_hip_motor">
      <!--<hardwareInterface>hardware_interface/EffortJointInterface</hardwareInterface>-->
      <mechanicalReduction>1</mechanicalReduction>
    </actuator>
  </transmission>
  <!-- Upper leg joint -->
  <joint name="L5_upper_joint" type="revolute">
    <parent link="L5_hipassembly"/>
    <child link="L5_upperleg"/>
    <axis xyz="0 1 0"/>
    <origin rpy="0 4.7124 0" xyz="0 0 -0.084982"/>
    <limit effort="500.0" lower="1.96405" upper="5.78886" velocity="12.0"/>
    <dynamics damping="0.1" friction="0.1"/>
    <!--<safety_controller k_position="50" k_velocity="10" soft_lower_limit="1.96405" soft_upper_limit="5.78886"/>-->
  </joint>
  <!-- Extensions -->
  <transmission name="L5_upper_tran">
    <type>transmission_interface/SimpleTransmission</type>
    <joint name="L5_upper_joint">
      <!--<hardwareInterface>hardware_interface/EffortJointInterface</hardwareInterface>-->
      <hardwareInterface>EffortJointInterface</hardwareInterface>
    </joint>
    <actuator name="L5_upper_motor">
      <!--<hardwareInterface>hardware_interface/EffortJointInterface</hardwareInterface>-->
      <mechanicalReduction>1</mechanicalReduction>
    </actuator>
  </transmission>
  <!-- Lower leg joint -->
  <joint name="L5_lower_joint" type="revolute">
    <parent link="L5_upperleg"/>
    <child link="L5_lowerleg"/>
    <axis xyz="0 1 0"/>
    <origin rpy="0 0 0" xyz="-0.300656 0 0"/>
    <limit effort="500.0" lower="-2.600884" upper="2.600884" velocity="12.0"/>
    <dynamics damping="0.1" friction="0.1"/>
    <!--<safety_controller k_position="50" k_velocity="10" soft_lower_limit="-2.600884" soft_upper_limit="2.600884"/>-->
  </joint>
  <!-- Extensions -->
  <transmission name="L5_lower_tran">
    <type>transmission_interface/SimpleTransmission</type>
    <joint name="L5_lower_joint">
      <!--<hardwareInterface>hardware_interface/EffortJointInterface</hardwareInterface>-->
      <hardwareInterface>EffortJointInterface</hardwareInterface>
    </joint>
    <actuator name="L5_lower_motor">
      <!--<hardwareInterface>hardware_interface/EffortJointInterface</hardwareInterface>-->
      <mechanicalReduction>1</mechanicalReduction>
    </actuator>
  </transmission>
  <!-- Foot joint -->
  <joint name="L5_foot_joint" type="fixed">
    <origin rpy="0 0 0" xyz="-0.283335 0 0"/>
    <parent link="L5_lowerleg"/>
    <child link="L5_foot"/>
  </joint>
  <!-- Links -->
  <!-- Hip assembly link -->
  <link name="L5_hipassembly">
    <inertial>
      <origin xyz="-0.02923 0. -0.0271748"/>
      <mass value="1.0"/>
      <inertia ixx="0.00871" ixy="-0.000001" ixz="-0.000001" iyy="0.00301" iyz="0.000002" izz="0.00871"/>
    </inertial>
    <visual>
      <geometry>
        <mesh filename="/home/dada/mujoco/qz2_urdf/qz2_meshes/r1.STL" scale="0.001 0.001 0.001"/>
      </geometry>
      <origin rpy="1.570795 0 1.570795" xyz="-0.050293 0 0"/>
      <material name="grey">
        <color rgba="1.0 1.0 1.0 0.3"/>
      </material>
    </visual>
    <collision>
      <geometry>
        <mesh filename="/home/dada/mujoco/qz2_urdf/qz2_meshes/r1.STL" scale="0.001 0.001 0.001"/>
      </geometry>
      <origin rpy="1.570795 0 1.570795" xyz="-0.050293 0 0"/>
    </collision>
  </link>
  <!-- Upper leg link -->
  <link name="L5_upperleg">
    <inertial>
      <origin xyz="-0.115692 0. 0."/>
      <mass value="0.9"/>
      <inertia ixx="0.00188" ixy="0.000002" ixz="-0.000001" iyy="0.01519" iyz="-0.000002" izz="0.01511"/>
    </inertial>
    <visual>
      <geometry>
        <mesh filename="/home/dada/mujoco/qz2_urdf/qz2_meshes/upperLeg.STL" scale="0.001 0.001 0.001"/>
      </geometry>
      <origin rpy="-1.570795 0 1.570795" xyz="0 0 0"/>
      <material name="grey">
        <color rgba="1.0 1.0 1.0 0.3"/>
      </material>
    </visual>
    <collision>
      <geometry>
        <mesh filename="/home/dada/mujoco/qz2_urdf/qz2_meshes/upperLeg.STL" scale="0.001 0.001 0.001"/>
      </geometry>
      <origin rpy="-1.570795 0 1.570795" xyz="0 0 0"/>
    </collision>
  </link>
  <!-- Extensions -->
  <!-- Lower leg link -->
  <link name="L5_lowerleg">
    <inertial>
      <!-- <origin xyz="-0.000000799 0.000008540 0.124197800"/> -->
      <origin xyz="-0.124198 0.0 0.0"/>
      <mass value="0.7"/>
      <inertia ixx="0.00037" ixy="0.000001" ixz="-0.000006" iyy="0.008233" iyz="0.0" izz="0.008256"/>
    </inertial>
    <visual>
      <geometry>
        <mesh filename="/home/dada/mujoco/qz2_urdf/qz2_meshes/lowerLeg.STL" scale="0.001 0.001 0.001"/>
      </geometry>
      <origin rpy="-1.570795 0 1.570795" xyz="0 0 0"/>
      <material name="grey">
        <color rgba="1.0 1.0 1.0 0.3"/>
      </material>
    </visual>
    <collision>
      <geometry>
        <mesh filename="/home/dada/mujoco/qz2_urdf/qz2_meshes/lowerLeg.STL" scale="0.001 0.001 0.001"/>
      </geometry>
      <origin rpy="-1.570795 0 1.570795" xyz="0 0 0"/>
    </collision>
  </link>
  <!-- Extensions -->
  <!-- Foot link -->
  <link name="L5_foot">
    <visual>
      <geometry>
        <mesh filename="/home/dada/mujoco/qz2_urdf/qz2_meshes/tip.STL" scale="0.001 0.001 0.001"/>
      </geometry>
      <origin rpy="0 -1.570795 0" xyz="0 0 0"/>
      <material name="endgrey">
        <color rgba="1.0 1.0 1.0 0.6"/>
      </material>
    </visual>
    <collision>
      <origin rpy="0 -1.570795 0" xyz="0 0 0"/>
      <geometry>
        <mesh filename="/home/dada/mujoco/qz2_urdf/qz2_meshes/tip.STL" scale="0.001 0.001 0.001"/>
      </geometry>
    </collision>
  </link>
  <!-- Extensions -->
  <mujoco>
    <compiler balanceinertia="true" discardvisual="false" meshdir="./qz2_meshes/"/>
  </mujoco>
</robot>

